Workbook

Sheet Sheet1
A1: Day | B1: Timing | C1: Team 1 | D1: Team 2 | G1: Format | H1: Participant 1 | I1: Participant 2 | J1: Winner | K1: Score | L1: Winning Team
A2: Day 1 | B2: Lunch Break | C2: A1 | D2: A2 | F2: A1+A2 | G2: Women's Singles | H2: =INDEX('[1]Team & Players'!$C$2:$C$7,MATCH(C2,'[1]Team & Players'!$A$2:$A$7,0)) -> Amrutha | I2: =INDEX('[1]Team & Players'!$C$2:$C$7,MATCH(D2,'[1]Team & Players'!$A$2:$A$7,0)) -> Vaishnavi M | L2: =IF(J2="","",IF(J2=H2,C2,D2))
A3: Day 1 | B3: Lunch Break | C3: A1 | D3: A2 | F3: A1+A2 | G3: Women's Doubles | H3: =INDEX('[1]Team & Players'!$C$2:$C$7,MATCH(C3,'[1]Team & Players'!$A$2:$A$7,0))&" + "&INDEX('[1]Team & Players'!$D$2:$D$7,MATCH(C3,'[1]Team & Players'!$A$2:$A$7,0)) -> Amrutha + Neha | I3: =INDEX('[1]Team & Players'!$C$2:$C$7,MATCH(D3,'[1]Team & Players'!$A$2:$A$7,0))&" + "&INDEX('[1]Team & Players'!$D$2:$D$7,MATCH(D3,'[1]Team & Players'!$A$2:$A$7,0)) -> Vaishnavi M + Keerthana | L3: =IF(J3="","",IF(J3=H3,C3,D3))
A4: Day 1 | B4: Lunch Break | C4: A1 | D4: A2 | F4: A1+A2 | G4: Mixed Doubles | H4: =INDEX('[1]Team & Players'!$D$2:$D$7,MATCH(C4,'[1]Team & Players'!$A$2:$A$7,0))&" + "&INDEX('[1]Team & Players'!$K$2:$K$7,MATCH(C4,'[1]Team & Players'!$A$2:$A$7,0)) -> Neha + Dhruv Jaju | I4: =INDEX('[1]Team & Players'!$D$2:$D$7,MATCH(D4,'[1]Team & Players'!$A$2:$A$7,0))&" + "&INDEX('[1]Team & Players'!$K$2:$K$7,MATCH(D4,'[1]Team & Players'!$A$2:$A$7,0)) -> Keerthana + Abhiram | L4: =IF(J4="","",IF(J4=H4,C4,D4))
A5: Day 1 | B5: Lunch Break | C5: A1 | D5: A2 | F5: A1+A2 | G5: Men's Singles 1 | H5: =INDEX('[1]Team & Players'!$E$2:$E$7,MATCH(C5,'[1]Team & Players'!$A$2:$A$7,0)) -> Saurabh | I5: =INDEX('[1]Team & Players'!$E$2:$E$7,MATCH(D5,'[1]Team & Players'!$A$2:$A$7,0)) -> Dhruv C | L5: =IF(J5="","",IF(J5=H5,C5,D5))
A6: Day 1 | B6: Lunch Break | C6: A1 | D6: A2 | F6: A1+A2 | G6: Men's Singles 2 | H6: =INDEX('[1]Team & Players'!$F$2:$F$7,MATCH(C6,'[1]Team & Players'!$A$2:$A$7,0)) -> Aman Doshi | I6: =INDEX('[1]Team & Players'!$F$2:$F$7,MATCH(D6,'[1]Team & Players'!$A$2:$A$7,0)) -> Avaneesh | L6: =IF(J6="","",IF(J6=H6,C6,D6))
A7: Day 1 | B7: Lunch Break | C7: A1 | D7: A2 | F7: A1+A2 | G7: Men's Doubles 1 | H7: =INDEX('[1]Team & Players'!$G$2:$G$7,MATCH(C7,'[1]Team & Players'!$A$2:$A$7,0))&" + "&INDEX('[1]Team & Players'!$H$2:$H$7,MATCH(C7,'[1]Team & Players'!$A$2:$A$7,0)) -> Nikhil M + Jinendar | I7: =INDEX('[1]Team & Players'!$G$2:$G$7,MATCH(D7,'[1]Team & Players'!$A$2:$A$7,0))&" + "&INDEX('[1]Team & Players'!$H$2:$H$7,MATCH(D7,'[1]Team & Players'!$A$2:$A$7,0)) -> Kushal + Shubham | L7: =IF(J7="","",IF(J7=H7,C7,D7))
A8: Day 1 | B8: Lunch Break | C8: A1 | D8: A2 | F8: A1+A2 | G8: Men's Doubles 2 | H8: =INDEX('[1]Team & Players'!$I$2:$I$7,MATCH(C8,'[1]Team & Players'!$A$2:$A$7,0))&" + "&INDEX('[1]Team & Players'!$J$2:$J$7,MATCH(C8,'[1]Team & Players'!$A$2:$A$7,0)) -> Sreesha + Manan | I8: =INDEX('[1]Team & Players'!$I$2:$I$7,MATCH(D8,'[1]Team & Players'!$A$2:$A$7,0))&" + "&INDEX('[1]Team & Players'!$J$2:$J$7,MATCH(D8,'[1]Team & Players'!$A$2:$A$7,0)) -> Yuvraj + Karthik KB | L8: =IF(J8="","",IF(J8=H8,C8,D8))
A9: Day 1 | B9: Post Office Hours | C9: A3 | D9: B3 | F9: A3+B3 | G9: Women's Singles | H9: =INDEX('[1]Team & Players'!$C$2:$C$7,MATCH(C9,'[1]Team & Players'!$A$2:$A$7,0)) -> Mamta | I9: =INDEX('[1]Team & Players'!$C$2:$C$7,MATCH(D9,'[1]Team & Players'!$A$2:$A$7,0)) -> Neha P Jain | L9: =IF(J9="","",IF(J9=H9,C9,D9))
A10: Day 1 | B10: Post Office Hours | C10: A3 | D10: B3 | F10: A3+B3 | G10: Women's Doubles | H10: =INDEX('[1]Team & Players'!$C$2:$C$7,MATCH(C10,'[1]Team & Players'!$A$2:$A$7,0))&" + "&INDEX('[1]Team & Players'!$D$2:$D$7,MATCH(C10,'[1]Team & Players'!$A$2:$A$7,0)) -> Mamta + Rithu | I10: =INDEX('[1]Team & Players'!$C$2:$C$7,MATCH(D10,'[1]Team & Players'!$A$2:$A$7,0))&" + "&INDEX('[1]Team & Players'!$D$2:$D$7,MATCH(D10,'[1]Team & Players'!$A$2:$A$7,0)) -> Neha P Jain + Drishti | L10: =IF(J10="","",IF(J10=H10,C10,D10))
A11: Day 1 | B11: Post Office Hours | C11: A3 | D11: B3 | F11: A3+B3 | G11: Mixed Doubles | H11: =INDEX('[1]Team & Players'!$D$2:$D$7,MATCH(C11,'[1]Team & Players'!$A$2:$A$7,0))&" + "&INDEX('[1]Team & Players'!$K$2:$K$7,MATCH(C11,'[1]Team & Players'!$A$2:$A$7,0)) -> Rithu + Darshan Patel | I11: =INDEX('[1]Team & Players'!$D$2:$D$7,MATCH(D11,'[1]Team & Players'!$A$2:$A$7,0))&" + "&INDEX('[1]Team & Players'!$K$2:$K$7,MATCH(D11,'[1]Team & Players'!$A$2:$A$7,0)) -> Drishti + Sanath | L11: =IF(J11="","",IF(J11=H11,C11,D11))
A12: Day 1 | B12: Post Office Hours | C12: A3 | D12: B3 | F12: A3+B3 | G12: Men's Singles 1 | H12: =INDEX('[1]Team & Players'!$E$2:$E$7,MATCH(C12,'[1]Team & Players'!$A$2:$A$7,0)) -> Sujal | I12: =INDEX('[1]Team & Players'!$E$2:$E$7,MATCH(D12,'[1]Team & Players'!$A$2:$A$7,0)) -> Anshul | L12: =IF(J12="","",IF(J12=H12,C12,D12))
A13: Day 1 | B13: Post Office Hours | C13: A3 | D13: B3 | F13: A3+B3 | G13: Men's Singles 2 | H13: =INDEX('[1]Team & Players'!$F$2:$F$7,MATCH(C13,'[1]Team & Players'!$A$2:$A$7,0)) -> Niraj Salot | I13: =INDEX('[1]Team & Players'!$F$2:$F$7,MATCH(D13,'[1]Team & Players'!$A$2:$A$7,0)) -> Navtej | L13: =IF(J13="","",IF(J13=H13,C13,D13))
A14: Day 1 | B14: Post Office Hours | C14: A3 | D14: B3 | F14: A3+B3 | G14: Men's Doubles 1 | H14: =INDEX('[1]Team & Players'!$G$2:$G$7,MATCH(C14,'[1]Team & Players'!$A$2:$A$7,0))&" + "&INDEX('[1]Team & Players'!$H$2:$H$7,MATCH(C14,'[1]Team & Players'!$A$2:$A$7,0)) -> Kunal D + Anirudha H | I14: =INDEX('[1]Team & Players'!$G$2:$G$7,MATCH(D14,'[1]Team & Players'!$A$2:$A$7,0))&" + "&INDEX('[1]Team & Players'!$H$2:$H$7,MATCH(D14,'[1]Team & Players'!$A$2:$A$7,0)) -> Nagarajan + Chandrashaker Joshi | L14: =IF(J14="","",IF(J14=H14,C14,D14))
A15: Day 1 | B15: Post Office Hours | C15: A3 | D15: B3 | F15: A3+B3 | G15: Men's Doubles 2 | H15: =INDEX('[1]Team & Players'!$I$2:$I$7,MATCH(C15,'[1]Team & Players'!$A$2:$A$7,0))&" + "&INDEX('[1]Team & Players'!$J$2:$J$7,MATCH(C15,'[1]Team & Players'!$A$2:$A$7,0)) -> Sarvesh H + Deviprasad | I15: =INDEX('[1]Team & Players'!$I$2:$I$7,MATCH(D15,'[1]Team & Players'!$A$2:$A$7,0))&" + "&INDEX('[1]Team & Players'!$J$2:$J$7,MATCH(D15,'[1]Team & Players'!$A$2:$A$7,0)) -> Rohan + Bhuvanesh | L15: =IF(J15="","",IF(J15=H15,C15,D15))
A16: Day 2 | B16: Lunch Break | C16: B1 | D16: B2 | F16: B1+B2 | G16: Women's Singles | H16: =INDEX('[1]Team & Players'!$C$2:$C$7,MATCH(C16,'[1]Team & Players'!$A$2:$A$7,0)) -> Subashree | I16: =INDEX('[1]Team & Players'!$C$2:$C$7,MATCH(D16,'[1]Team & Players'!$A$2:$A$7,0)) -> Riya | L16: =IF(J16="","",IF(J16=H16,C16,D16))
A17: Day 2 | B17: Lunch Break | C17: B1 | D17: B2 | F17: B1+B2 | G17: Women's Doubles | H17: =INDEX('[1]Team & Players'!$C$2:$C$7,MATCH(C17,'[1]Team & Players'!$A$2:$A$7,0))&" + "&INDEX('[1]Team & Players'!$D$2:$D$7,MATCH(C17,'[1]Team & Players'!$A$2:$A$7,0)) -> Subashree + Sanjana | I17: =INDEX('[1]Team & Players'!$C$2:$C$7,MATCH(D17,'[1]Team & Players'!$A$2:$A$7,0))&" + "&INDEX('[1]Team & Players'!$D$2:$D$7,MATCH(D17,'[1]Team & Players'!$A$2:$A$7,0)) -> Riya + Yukti | L17: =IF(J17="","",IF(J17=H17,C17,D17))
A18: Day 2 | B18: Lunch Break | C18: B1 | D18: B2 | F18: B1+B2 | G18: Mixed Doubles | H18: =INDEX('[1]Team & Players'!$D$2:$D$7,MATCH(C18,'[1]Team & Players'!$A$2:$A$7,0))&" + "&INDEX('[1]Team & Players'!$K$2:$K$7,MATCH(C18,'[1]Team & Players'!$A$2:$A$7,0)) -> Sanjana + Bharatha S | I18: =INDEX('[1]Team & Players'!$D$2:$D$7,MATCH(D18,'[1]Team & Players'!$A$2:$A$7,0))&" + "&INDEX('[1]Team & Players'!$K$2:$K$7,MATCH(D18,'[1]Team & Players'!$A$2:$A$7,0)) -> Yukti + Niranjan | L18: =IF(J18="","",IF(J18=H18,C18,D18))
A19: Day 2 | B19: Lunch Break | C19: B1 | D19: B2 | F19: B1+B2 | G19: Men's Singles 1 | H19: =INDEX('[1]Team & Players'!$E$2:$E$7,MATCH(C19,'[1]Team & Players'!$A$2:$A$7,0)) -> Naman | I19: =INDEX('[1]Team & Players'!$E$2:$E$7,MATCH(D19,'[1]Team & Players'!$A$2:$A$7,0)) -> Pavan D | L19: =IF(J19="","",IF(J19=H19,C19,D19))
A20: Day 2 | B20: Lunch Break | C20: B1 | D20: B2 | F20: B1+B2 | G20: Men's Singles 2 | H20: =INDEX('[1]Team & Players'!$F$2:$F$7,MATCH(C20,'[1]Team & Players'!$A$2:$A$7,0)) -> Jay B | I20: =INDEX('[1]Team & Players'!$F$2:$F$7,MATCH(D20,'[1]Team & Players'!$A$2:$A$7,0)) -> Vidwan | L20: =IF(J20="","",IF(J20=H20,C20,D20))
A21: Day 2 | B21: Lunch Break | C21: B1 | D21: B2 | F21: B1+B2 | G21: Men's Doubles 1 | H21: =INDEX('[1]Team & Players'!$G$2:$G$7,MATCH(C21,'[1]Team & Players'!$A$2:$A$7,0))&" + "&INDEX('[1]Team & Players'!$H$2:$H$7,MATCH(C21,'[1]Team & Players'!$A$2:$A$7,0)) -> Leela Sagar + Ali Akbar | I21: =INDEX('[1]Team & Players'!$G$2:$G$7,MATCH(D21,'[1]Team & Players'!$A$2:$A$7,0))&" + "&INDEX('[1]Team & Players'!$H$2:$H$7,MATCH(D21,'[1]Team & Players'!$A$2:$A$7,0)) -> Shravanth + Vrishin | L21: =IF(J21="","",IF(J21=H21,C21,D21))
A22: Day 2 | B22: Lunch Break | C22: B1 | D22: B2 | F22: B1+B2 | G22: Men's Doubles 2 | H22: =INDEX('[1]Team & Players'!$I$2:$I$7,MATCH(C22,'[1]Team & Players'!$A$2:$A$7,0))&" + "&INDEX('[1]Team & Players'!$J$2:$J$7,MATCH(C22,'[1]Team & Players'!$A$2:$A$7,0)) -> Khush B + Hemanth | I22: =INDEX('[1]Team & Players'!$I$2:$I$7,MATCH(D22,'[1]Team & Players'!$A$2:$A$7,0))&" + "&INDEX('[1]Team & Players'!$J$2:$J$7,MATCH(D22,'[1]Team & Players'!$A$2:$A$7,0)) -> Rohith + Darshan H | L22: =IF(J22="","",IF(J22=H22,C22,D22))
A23: Day 2 | B23: Post Office Hours | C23: A1 | D23: A3 | F23: A1+A3 | G23: Women's Singles | H23: =INDEX('[1]Team & Players'!$C$2:$C$7,MATCH(C23,'[1]Team & Players'!$A$2:$A$7,0)) -> Amrutha | I23: =INDEX('[1]Team & Players'!$C$2:$C$7,MATCH(D23,'[1]Team & Players'!$A$2:$A$7,0)) -> Mamta | L23: =IF(J23="","",IF(J23=H23,C23,D23))
A24: Day 2 | B24: Post Office Hours | C24: A1 | D24: A3 | F24: A1+A3 | G24: Women's Doubles | H24: =INDEX('[1]Team & Players'!$C$2:$C$7,MATCH(C24,'[1]Team & Players'!$A$2:$A$7,0))&" + "&INDEX('[1]Team & Players'!$D$2:$D$7,MATCH(C24,'[1]Team & Players'!$A$2:$A$7,0)) -> Amrutha + Neha | I24: =INDEX('[1]Team & Players'!$C$2:$C$7,MATCH(D24,'[1]Team & Players'!$A$2:$A$7,0))&" + "&INDEX('[1]Team & Players'!$D$2:$D$7,MATCH(D24,'[1]Team & Players'!$A$2:$A$7,0)) -> Mamta + Rithu | L24: =IF(J24="","",IF(J24=H24,C24,D24))
A25: Day 2 | B25: Post Office Hours | C25: A1 | D25: A3 | F25: A1+A3 | G25: Mixed Doubles | H25: =INDEX('[1]Team & Players'!$D$2:$D$7,MATCH(C25,'[1]Team & Players'!$A$2:$A$7,0))&" + "&INDEX('[1]Team & Players'!$K$2:$K$7,MATCH(C25,'[1]Team & Players'!$A$2:$A$7,0)) -> Neha + Dhruv Jaju | I25: =INDEX('[1]Team & Players'!$D$2:$D$7,MATCH(D25,'[1]Team & Players'!$A$2:$A$7,0))&" + "&INDEX('[1]Team & Players'!$K$2:$K$7,MATCH(D25,'[1]Team & Players'!$A$2:$A$7,0)) -> Rithu + Darshan Patel | L25: =IF(J25="","",IF(J25=H25,C25,D25))
A26: Day 2 | B26: Post Office Hours | C26: A1 | D26: A3 | F26: A1+A3 | G26: Men's Singles 1 | H26: =INDEX('[1]Team & Players'!$E$2:$E$7,MATCH(C26,'[1]Team & Players'!$A$2:$A$7,0)) -> Saurabh | I26: =INDEX('[1]Team & Players'!$E$2:$E$7,MATCH(D26,'[1]Team & Players'!$A$2:$A$7,0)) -> Sujal | L26: =IF(J26="","",IF(J26=H26,C26,D26))
A27: Day 2 | B27: Post Office Hours | C27: A1 | D27: A3 | F27: A1+A3 | G27: Men's Singles 2 | H27: =INDEX('[1]Team & Players'!$F$2:$F$7,MATCH(C27,'[1]Team & Players'!$A$2:$A$7,0)) -> Aman Doshi | I27: =INDEX('[1]Team & Players'!$F$2:$F$7,MATCH(D27,'[1]Team & Players'!$A$2:$A$7,0)) -> Niraj Salot | L27: =IF(J27="","",IF(J27=H27,C27,D27))
A28: Day 2 | B28: Post Office Hours | C28: A1 | D28: A3 | F28: A1+A3 | G28: Men's Doubles 1 | H28: =INDEX('[1]Team & Players'!$G$2:$G$7,MATCH(C28,'[1]Team & Players'!$A$2:$A$7,0))&" + "&INDEX('[1]Team & Players'!$H$2:$H$7,MATCH(C28,'[1]Team & Players'!$A$2:$A$7,0)) -> Nikhil M + Jinendar | I28: =INDEX('[1]Team & Players'!$G$2:$G$7,MATCH(D28,'[1]Team & Players'!$A$2:$A$7,0))&" + "&INDEX('[1]Team & Players'!$H$2:$H$7,MATCH(D28,'[1]Team & Players'!$A$2:$A$7,0)) -> Kunal D + Anirudha H | L28: =IF(J28="","",IF(J28=H28,C28,D28))
A29: Day 2 | B29: Post Office Hours | C29: A1 | D29: A3 | F29: A1+A3 | G29: Men's Doubles 2 | H29: =INDEX('[1]Team & Players'!$I$2:$I$7,MATCH(C29,'[1]Team & Players'!$A$2:$A$7,0))&" + "&INDEX('[1]Team & Players'!$J$2:$J$7,MATCH(C29,'[1]Team & Players'!$A$2:$A$7,0)) -> Sreesha + Manan | I29: =INDEX('[1]Team & Players'!$I$2:$I$7,MATCH(D29,'[1]Team & Players'!$A$2:$A$7,0))&" + "&INDEX('[1]Team & Players'!$J$2:$J$7,MATCH(D29,'[1]Team & Players'!$A$2:$A$7,0)) -> Sarvesh H + Deviprasad | L29: =IF(J29="","",IF(J29=H29,C29,D29))
A30: Day 3 | B30: Lunch Break | C30: A2 | D30: B1 | F30: A2+B1 | G30: Women's Singles | H30: =INDEX('[1]Team & Players'!$C$2:$C$7,MATCH(C30,'[1]Team & Players'!$A$2:$A$7,0)) -> Vaishnavi M | I30: =INDEX('[1]Team & Players'!$C$2:$C$7,MATCH(D30,'[1]Team & Players'!$A$2:$A$7,0)) -> Subashree | L30: =IF(J30="","",IF(J30=H30,C30,D30))
A31: Day 3 | B31: Lunch Break | C31: A2 | D31: B1 | F31: A2+B1 | G31: Women's Doubles | H31: =INDEX('[1]Team & Players'!$C$2:$C$7,MATCH(C31,'[1]Team & Players'!$A$2:$A$7,0))&" + "&INDEX('[1]Team & Players'!$D$2:$D$7,MATCH(C31,'[1]Team & Players'!$A$2:$A$7,0)) -> Vaishnavi M + Keerthana | I31: =INDEX('[1]Team & Players'!$C$2:$C$7,MATCH(D31,'[1]Team & Players'!$A$2:$A$7,0))&" + "&INDEX('[1]Team & Players'!$D$2:$D$7,MATCH(D31,'[1]Team & Players'!$A$2:$A$7,0)) -> Subashree + Sanjana | L31: =IF(J31="","",IF(J31=H31,C31,D31))
A32: Day 3 | B32: Lunch Break | C32: A2 | D32: B1 | F32: A2+B1 | G32: Mixed Doubles | H32: =INDEX('[1]Team & Players'!$D$2:$D$7,MATCH(C32,'[1]Team & Players'!$A$2:$A$7,0))&" + "&INDEX('[1]Team & Players'!$K$2:$K$7,MATCH(C32,'[1]Team & Players'!$A$2:$A$7,0)) -> Keerthana + Abhiram | I32: =INDEX('[1]Team & Players'!$D$2:$D$7,MATCH(D32,'[1]Team & Players'!$A$2:$A$7,0))&" + "&INDEX('[1]Team & Players'!$K$2:$K$7,MATCH(D32,'[1]Team & Players'!$A$2:$A$7,0)) -> Sanjana + Bharatha S | L32: =IF(J32="","",IF(J32=H32,C32,D32))
A33: Day 3 | B33: Lunch Break | C33: A2 | D33: B1 | F33: A2+B1 | G33: Men's Singles 1 | H33: =INDEX('[1]Team & Players'!$E$2:$E$7,MATCH(C33,'[1]Team & Players'!$A$2:$A$7,0)) -> Dhruv C | I33: =INDEX('[1]Team & Players'!$E$2:$E$7,MATCH(D33,'[1]Team & Players'!$A$2:$A$7,0)) -> Naman | L33: =IF(J33="","",IF(J33=H33,C33,D33))
A34: Day 3 | B34: Lunch Break | C34: A2 | D34: B1 | F34: A2+B1 | G34: Men's Singles 2 | H34: =INDEX('[1]Team & Players'!$F$2:$F$7,MATCH(C34,'[1]Team & Players'!$A$2:$A$7,0)) -> Avaneesh | I34: =INDEX('[1]Team & Players'!$F$2:$F$7,MATCH(D34,'[1]Team & Players'!$A$2:$A$7,0)) -> Jay B | L34: =IF(J34="","",IF(J34=H34,C34,D34))
A35: Day 3 | B35: Lunch Break | C35: A2 | D35: B1 | F35: A2+B1 | G35: Men's Doubles 1 | H35: =INDEX('[1]Team & Players'!$G$2:$G$7,MATCH(C35,'[1]Team & Players'!$A$2:$A$7,0))&" + "&INDEX('[1]Team & Players'!$H$2:$H$7,MATCH(C35,'[1]Team & Players'!$A$2:$A$7,0)) -> Kushal + Shubham | I35: =INDEX('[1]Team & Players'!$G$2:$G$7,MATCH(D35,'[1]Team & Players'!$A$2:$A$7,0))&" + "&INDEX('[1]Team & Players'!$H$2:$H$7,MATCH(D35,'[1]Team & Players'!$A$2:$A$7,0)) -> Leela Sagar + Ali Akbar | L35: =IF(J35="","",IF(J35=H35,C35,D35))
A36: Day 3 | B36: Lunch Break | C36: A2 | D36: B1 | F36: A2+B1 | G36: Men's Doubles 2 | H36: =INDEX('[1]Team & Players'!$I$2:$I$7,MATCH(C36,'[1]Team & Players'!$A$2:$A$7,0))&" + "&INDEX('[1]Team & Players'!$J$2:$J$7,MATCH(C36,'[1]Team & Players'!$A$2:$A$7,0)) -> Yuvraj + Karthik KB | I36: =INDEX('[1]Team & Players'!$I$2:$I$7,MATCH(D36,'[1]Team & Players'!$A$2:$A$7,0))&" + "&INDEX('[1]Team & Players'!$J$2:$J$7,MATCH(D36,'[1]Team & Players'!$A$2:$A$7,0)) -> Khush B + Hemanth | L36: =IF(J36="","",IF(J36=H36,C36,D36))
A37: Day 3 | B37: Post Office Hours | C37: B2 | D37: B3 | F37: B2+B3 | G37: Women's Singles | H37: =INDEX('[1]Team & Players'!$C$2:$C$7,MATCH(C37,'[1]Team & Players'!$A$2:$A$7,0)) -> Riya | I37: =INDEX('[1]Team & Players'!$C$2:$C$7,MATCH(D37,'[1]Team & Players'!$A$2:$A$7,0)) -> Neha P Jain | L37: =IF(J37="","",IF(J37=H37,C37,D37))
A38: Day 3 | B38: Post Office Hours | C38: B2 | D38: B3 | F38: B2+B3 | G38: Women's Doubles | H38: =INDEX('[1]Team & Players'!$C$2:$C$7,MATCH(C38,'[1]Team & Players'!$A$2:$A$7,0))&" + "&INDEX('[1]Team & Players'!$D$2:$D$7,MATCH(C38,'[1]Team & Players'!$A$2:$A$7,0)) -> Riya + Yukti | I38: =INDEX('[1]Team & Players'!$C$2:$C$7,MATCH(D38,'[1]Team & Players'!$A$2:$A$7,0))&" + "&INDEX('[1]Team & Players'!$D$2:$D$7,MATCH(D38,'[1]Team & Players'!$A$2:$A$7,0)) -> Neha P Jain + Drishti | L38: =IF(J38="","",IF(J38=H38,C38,D38))
A39: Day 3 | B39: Post Office Hours | C39: B2 | D39: B3 | F39: B2+B3 | G39: Mixed Doubles | H39: =INDEX('[1]Team & Players'!$D$2:$D$7,MATCH(C39,'[1]Team & Players'!$A$2:$A$7,0))&" + "&INDEX('[1]Team & Players'!$K$2:$K$7,MATCH(C39,'[1]Team & Players'!$A$2:$A$7,0)) -> Yukti + Niranjan | I39: =INDEX('[1]Team & Players'!$D$2:$D$7,MATCH(D39,'[1]Team & Players'!$A$2:$A$7,0))&" + "&INDEX('[1]Team & Players'!$K$2:$K$7,MATCH(D39,'[1]Team & Players'!$A$2:$A$7,0)) -> Drishti + Sanath | L39: =IF(J39="","",IF(J39=H39,C39,D39))
A40: Day 3 | B40: Post Office Hours | C40: B2 | D40: B3 | F40: B2+B3 | G40: Men's Singles 1 | H40: =INDEX('[1]Team & Players'!$E$2:$E$7,MATCH(C40,'[1]Team & Players'!$A$2:$A$7,0)) -> Pavan D | I40: =INDEX('[1]Team & Players'!$E$2:$E$7,MATCH(D40,'[1]Team & Players'!$A$2:$A$7,0)) -> Anshul | L40: =IF(J40="","",IF(J40=H40,C40,D40))
...

Sheet Shuffled Matches
B2: Day | C2: Timing | D2: Team 1 | E2: Team 2 | F2: Matches | G2: Format | H2: Participant 1 | I2: Participant 2 | J2: Winner | K2: Score (Team 1-Team 2) | L2: Winning Team | M2: Matches | N2: Team 1 Score | O2: Team 2 Score | P2: Score Difference
B3: Day 1 | C3: Lunch Break | D3: Team 5 | E3: Team 6 | F3: Team 5+Team 6 | G3: Mixed Doubles | H3: Yukti + Niranjan | I3: Drishti + Sanath | J3: =IF(K3="","",IFERROR(IF(--_xlfn.TEXTBEFORE(K3,"-")>--_xlfn.TEXTAFTER(K3,"-"),H3,IF(--_xlfn.TEXTAFTER(K3,"-")>--_xlfn.TEXTBEFORE(K3,"-"),I3,"Tie")),"Check score")) -> Yukti + Niranjan | K3: 21-16 | L3: =IF(K3="","",IFERROR(IF(--_xlfn.TEXTBEFORE(K3,"-")>--_xlfn.TEXTAFTER(K3,"-"),D3,IF(--_xlfn.TEXTAFTER(K3,"-")>--_xlfn.TEXTBEFORE(K3,"-"),E3,"Tie")),"Check score")) -> Team 5 | N3: =IFERROR(--_xlfn.TEXTBEFORE(K3,"-"),"") -> 21 | O3: =IFERROR(--_xlfn.TEXTAFTER(K3,"-"),"") -> 16 | P3: =IF(OR(N3="",O3=""),"",N3-O3) -> 5
B4: Day 1 | C4: Lunch Break | D4: Team 5 | E4: Team 6 | F4: Team 5+Team 6 | G4: Women's Singles | H4: Riya | I4: Neha P Jain | J4: =IF(K4="","",IFERROR(IF(--_xlfn.TEXTBEFORE(K4,"-")>--_xlfn.TEXTAFTER(K4,"-"),H4,IF(--_xlfn.TEXTAFTER(K4,"-")>--_xlfn.TEXTBEFORE(K4,"-"),I4,"Tie")),"Check score")) -> Neha P Jain | K4: 7-21 | L4: =IF(K4="","",IFERROR(IF(--_xlfn.TEXTBEFORE(K4,"-")>--_xlfn.TEXTAFTER(K4,"-"),D4,IF(--_xlfn.TEXTAFTER(K4,"-")>--_xlfn.TEXTBEFORE(K4,"-"),E4,"Tie")),"Check score")) -> Team 6 | N4: =IFERROR(--_xlfn.TEXTBEFORE(K4,"-"),"") -> 7 | O4: =IFERROR(--_xlfn.TEXTAFTER(K4,"-"),"") -> 21 | P4: =IF(OR(N4="",O4=""),"",N4-O4) -> -14
B5: Day 1 | C5: Lunch Break | D5: Team 1 | E5: Team 4 | F5: Team 1+Team 4 | G5: Women's Singles | H5: Amrutha | I5: Subashree | J5: =IF(K5="","",IFERROR(IF(--_xlfn.TEXTBEFORE(K5,"-")>--_xlfn.TEXTAFTER(K5,"-"),H5,IF(--_xlfn.TEXTAFTER(K5,"-")>--_xlfn.TEXTBEFORE(K5,"-"),I5,"Tie")),"Check score")) -> Subashree | K5: 7-21 | L5: =IF(K5="","",IFERROR(IF(--_xlfn.TEXTBEFORE(K5,"-")>--_xlfn.TEXTAFTER(K5,"-"),D5,IF(--_xlfn.TEXTAFTER(K5,"-")>--_xlfn.TEXTBEFORE(K5,"-"),E5,"Tie")),"Check score")) -> Team 4 | N5: =IFERROR(--_xlfn.TEXTBEFORE(K5,"-"),"") -> 7 | O5: =IFERROR(--_xlfn.TEXTAFTER(K5,"-"),"") -> 21 | P5: =IF(OR(N5="",O5=""),"",N5-O5) -> -14
B6: Day 1 | C6: Lunch Break | D6: Team 3 | E6: Team 4 | F6: Team 3+Team 4 | G6: Women's Singles | H6: Mamta | I6: Subashree | J6: =IF(K6="","",IFERROR(IF(--_xlfn.TEXTBEFORE(K6,"-")>--_xlfn.TEXTAFTER(K6,"-"),H6,IF(--_xlfn.TEXTAFTER(K6,"-")>--_xlfn.TEXTBEFORE(K6,"-"),I6,"Tie")),"Check score")) -> Mamta | K6: 21-19 | L6: =IF(K6="","",IFERROR(IF(--_xlfn.TEXTBEFORE(K6,"-")>--_xlfn.TEXTAFTER(K6,"-"),D6,IF(--_xlfn.TEXTAFTER(K6,"-")>--_xlfn.TEXTBEFORE(K6,"-"),E6,"Tie")),"Check score")) -> Team 3 | N6: =IFERROR(--_xlfn.TEXTBEFORE(K6,"-"),"") -> 21 | O6: =IFERROR(--_xlfn.TEXTAFTER(K6,"-"),"") -> 19 | P6: =IF(OR(N6="",O6=""),"",N6-O6) -> 2
B7: Day 1 | C7: Lunch Break | D7: Team 2 | E7: Team 3 | F7: Team 2+Team 3 | G7: Mixed Doubles | H7: Keerthana + Abhiram | I7: Rithu + Darshan Patel | J7: =IF(K7="","",IFERROR(IF(--_xlfn.TEXTBEFORE(K7,"-")>--_xlfn.TEXTAFTER(K7,"-"),H7,IF(--_xlfn.TEXTAFTER(K7,"-")>--_xlfn.TEXTBEFORE(K7,"-"),I7,"Tie")),"Check score")) -> Rithu + Darshan Patel | K7: 16-21 | L7: =IF(K7="","",IFERROR(IF(--_xlfn.TEXTBEFORE(K7,"-")>--_xlfn.TEXTAFTER(K7,"-"),D7,IF(--_xlfn.TEXTAFTER(K7,"-")>--_xlfn.TEXTBEFORE(K7,"-"),E7,"Tie")),"Check score")) -> Team 3 | N7: =IFERROR(--_xlfn.TEXTBEFORE(K7,"-"),"") -> 16 | O7: =IFERROR(--_xlfn.TEXTAFTER(K7,"-"),"") -> 21 | P7: =IF(OR(N7="",O7=""),"",N7-O7) -> -5
B8: Day 1 | C8: Lunch Break | D8: Team 1 | E8: Team 4 | F8: Team 1+Team 4 | G8: Men's Singles 2 | H8: Aman Doshi | I8: Jay B | J8: =IF(K8="","",IFERROR(IF(--_xlfn.TEXTBEFORE(K8,"-")>--_xlfn.TEXTAFTER(K8,"-"),H8,IF(--_xlfn.TEXTAFTER(K8,"-")>--_xlfn.TEXTBEFORE(K8,"-"),I8,"Tie")),"Check score")) -> Jay B | K8: 11-21 | L8: =IF(K8="","",IFERROR(IF(--_xlfn.TEXTBEFORE(K8,"-")>--_xlfn.TEXTAFTER(K8,"-"),D8,IF(--_xlfn.TEXTAFTER(K8,"-")>--_xlfn.TEXTBEFORE(K8,"-"),E8,"Tie")),"Check score")) -> Team 4 | N8: =IFERROR(--_xlfn.TEXTBEFORE(K8,"-"),"") -> 11 | O8: =IFERROR(--_xlfn.TEXTAFTER(K8,"-"),"") -> 21 | P8: =IF(OR(N8="",O8=""),"",N8-O8) -> -10
B9: Day 1 | C9: Lunch Break | D9: Team 1 | E9: Team 4 | F9: Team 1+Team 4 | G9: Women's Doubles | H9: Amrutha + Neha | I9: Subashree + Sanjana | J9: Amrutha + Neha | K9: 21-15 | L9: =IF(K9="","",IFERROR(IF(--_xlfn.TEXTBEFORE(K9,"-")>--_xlfn.TEXTAFTER(K9,"-"),D9,IF(--_xlfn.TEXTAFTER(K9,"-")>--_xlfn.TEXTBEFORE(K9,"-"),E9,"Tie")),"Check score")) -> Team 1 | N9: =IFERROR(--_xlfn.TEXTBEFORE(K9,"-"),"") -> 21 | O9: =IFERROR(--_xlfn.TEXTAFTER(K9,"-"),"") -> 15 | P9: =IF(OR(N9="",O9=""),"",N9-O9) -> 6
B10: Day 1 | C10: Post Office Hours | D10: Team 4 | E10: Team 5 | F10: Team 4+Team 5 | G10: Women's Singles | H10: Subashree | I10: Riya | J10: =IF(K10="","",IFERROR(IF(--_xlfn.TEXTBEFORE(K10,"-")>--_xlfn.TEXTAFTER(K10,"-"),H10,IF(--_xlfn.TEXTAFTER(K10,"-")>--_xlfn.TEXTBEFORE(K10,"-"),I10,"Tie")),"Check score")) -> Subashree | K10: 21-13 | L10: =IF(K10="","",IFERROR(IF(--_xlfn.TEXTBEFORE(K10,"-")>--_xlfn.TEXTAFTER(K10,"-"),D10,IF(--_xlfn.TEXTAFTER(K10,"-")>--_xlfn.TEXTBEFORE(K10,"-"),E10,"Tie")),"Check score")) -> Team 4 | N10: =IFERROR(--_xlfn.TEXTBEFORE(K10,"-"),"") -> 21 | O10: =IFERROR(--_xlfn.TEXTAFTER(K10,"-"),"") -> 13 | P10: =IF(OR(N10="",O10=""),"",N10-O10) -> 8
B11: Day 1 | C11: Post Office Hours | D11: Team 3 | E11: Team 5 | F11: Team 3+Team 5 | G11: Men's Singles 2 | H11: Niraj Salot | I11: Vidwan | J11: =IF(K11="","",IFERROR(IF(--_xlfn.TEXTBEFORE(K11,"-")>--_xlfn.TEXTAFTER(K11,"-"),H11,IF(--_xlfn.TEXTAFTER(K11,"-")>--_xlfn.TEXTBEFORE(K11,"-"),I11,"Tie")),"Check score")) -> Vidwan | K11: 11-21 | L11: =IF(K11="","",IFERROR(IF(--_xlfn.TEXTBEFORE(K11,"-")>--_xlfn.TEXTAFTER(K11,"-"),D11,IF(--_xlfn.TEXTAFTER(K11,"-")>--_xlfn.TEXTBEFORE(K11,"-"),E11,"Tie")),"Check score")) -> Team 5 | N11: =IFERROR(--_xlfn.TEXTBEFORE(K11,"-"),"") -> 11 | O11: =IFERROR(--_xlfn.TEXTAFTER(K11,"-"),"") -> 21 | P11: =IF(OR(N11="",O11=""),"",N11-O11) -> -10
B12: Day 1 | C12: Post Office Hours | D12: Team 5 | E12: Team 6 | F12: Team 5+Team 6 | G12: Men's Doubles 1 | H12: Shravanth + Vrishin | I12: Nagarajan + Chandrashaker Joshi | J12: =IF(K12="","",IFERROR(IF(--_xlfn.TEXTBEFORE(K12,"-")>--_xlfn.TEXTAFTER(K12,"-"),H12,IF(--_xlfn.TEXTAFTER(K12,"-")>--_xlfn.TEXTBEFORE(K12,"-"),I12,"Tie")),"Check score")) -> Nagarajan + Chandrashaker Joshi | K12: 18-21 | L12: =IF(K12="","",IFERROR(IF(--_xlfn.TEXTBEFORE(K12,"-")>--_xlfn.TEXTAFTER(K12,"-"),D12,IF(--_xlfn.TEXTAFTER(K12,"-")>--_xlfn.TEXTBEFORE(K12,"-"),E12,"Tie")),"Check score")) -> Team 6 | N12: =IFERROR(--_xlfn.TEXTBEFORE(K12,"-"),"") -> 18 | O12: =IFERROR(--_xlfn.TEXTAFTER(K12,"-"),"") -> 21 | P12: =IF(OR(N12="",O12=""),"",N12-O12) -> -3
B13: Day 1 | C13: Post Office Hours | D13: Team 2 | E13: Team 4 | F13: Team 2+Team 4 | G13: Men's Doubles 2 | H13: Yuvraj + Karthik KB | I13: Khush B + Hemanth | J13: =IF(K13="","",IFERROR(IF(--_xlfn.TEXTBEFORE(K13,"-")>--_xlfn.TEXTAFTER(K13,"-"),H13,IF(--_xlfn.TEXTAFTER(K13,"-")>--_xlfn.TEXTBEFORE(K13,"-"),I13,"Tie")),"Check score")) -> Yuvraj + Karthik KB | K13: 21-16 | L13: =IF(K13="","",IFERROR(IF(--_xlfn.TEXTBEFORE(K13,"-")>--_xlfn.TEXTAFTER(K13,"-"),D13,IF(--_xlfn.TEXTAFTER(K13,"-")>--_xlfn.TEXTBEFORE(K13,"-"),E13,"Tie")),"Check score")) -> Team 2 | N13: =IFERROR(--_xlfn.TEXTBEFORE(K13,"-"),"") -> 21 | O13: =IFERROR(--_xlfn.TEXTAFTER(K13,"-"),"") -> 16 | P13: =IF(OR(N13="",O13=""),"",N13-O13) -> 5
B14: Day 1 | C14: Post Office Hours | D14: Team 1 | E14: Team 5 | F14: Team 1+Team 5 | G14: Men's Doubles 1 | H14: Nikhil M + Jinendar | I14: Shravanth + Vrishin | J14: =IF(K14="","",IFERROR(IF(--_xlfn.TEXTBEFORE(K14,"-")>--_xlfn.TEXTAFTER(K14,"-"),H14,IF(--_xlfn.TEXTAFTER(K14,"-")>--_xlfn.TEXTBEFORE(K14,"-"),I14,"Tie")),"Check score")) -> Nikhil M + Jinendar | K14: 21-11 | L14: =IF(K14="","",IFERROR(IF(--_xlfn.TEXTBEFORE(K14,"-")>--_xlfn.TEXTAFTER(K14,"-"),D14,IF(--_xlfn.TEXTAFTER(K14,"-")>--_xlfn.TEXTBEFORE(K14,"-"),E14,"Tie")),"Check score")) -> Team 1 | N14: =IFERROR(--_xlfn.TEXTBEFORE(K14,"-"),"") -> 21 | O14: =IFERROR(--_xlfn.TEXTAFTER(K14,"-"),"") -> 11 | P14: =IF(OR(N14="",O14=""),"",N14-O14) -> 10
B15: Day 1 | C15: Post Office Hours | D15: Team 4 | E15: Team 6 | F15: Team 4+Team 6 | G15: Women's Doubles | H15: Subashree + Sanjana | I15: Neha P Jain + Drishti | J15: =IF(K15="","",IFERROR(IF(--_xlfn.TEXTBEFORE(K15,"-")>--_xlfn.TEXTAFTER(K15,"-"),H15,IF(--_xlfn.TEXTAFTER(K15,"-")>--_xlfn.TEXTBEFORE(K15,"-"),I15,"Tie")),"Check score")) -> Subashree + Sanjana | K15: 21-11 | L15: =IF(K15="","",IFERROR(IF(--_xlfn.TEXTBEFORE(K15,"-")>--_xlfn.TEXTAFTER(K15,"-"),D15,IF(--_xlfn.TEXTAFTER(K15,"-")>--_xlfn.TEXTBEFORE(K15,"-"),E15,"Tie")),"Check score")) -> Team 4 | N15: =IFERROR(--_xlfn.TEXTBEFORE(K15,"-"),"") -> 21 | O15: =IFERROR(--_xlfn.TEXTAFTER(K15,"-"),"") -> 11 | P15: =IF(OR(N15="",O15=""),"",N15-O15) -> 10
B16: Day 1 | C16: Post Office Hours | D16: Team 1 | E16: Team 3 | F16: Team 1+Team 3 | G16: Women's Doubles | H16: Amrutha + Neha | I16: Mamta + Rithu | J16: =IF(K16="","",IFERROR(IF(--_xlfn.TEXTBEFORE(K16,"-")>--_xlfn.TEXTAFTER(K16,"-"),H16,IF(--_xlfn.TEXTAFTER(K16,"-")>--_xlfn.TEXTBEFORE(K16,"-"),I16,"Tie")),"Check score")) -> Amrutha + Neha | K16: 21-13 | L16: =IF(K16="","",IFERROR(IF(--_xlfn.TEXTBEFORE(K16,"-")>--_xlfn.TEXTAFTER(K16,"-"),D16,IF(--_xlfn.TEXTAFTER(K16,"-")>--_xlfn.TEXTBEFORE(K16,"-"),E16,"Tie")),"Check score")) -> Team 1 | N16: =IFERROR(--_xlfn.TEXTBEFORE(K16,"-"),"") -> 21 | O16: =IFERROR(--_xlfn.TEXTAFTER(K16,"-"),"") -> 13 | P16: =IF(OR(N16="",O16=""),"",N16-O16) -> 8
B17: Day 2 | C17: Lunch Break | D17: Team 3 | E17: Team 6 | F17: Team 3+Team 6 | G17: Men's Doubles 1 | H17: Kunal D + Anirudha H | I17: Nagarajan + Chandrashaker Joshi | J17: =IF(K17="","",IFERROR(IF(--_xlfn.TEXTBEFORE(K17,"-")>--_xlfn.TEXTAFTER(K17,"-"),H17,IF(--_xlfn.TEXTAFTER(K17,"-")>--_xlfn.TEXTBEFORE(K17,"-"),I17,"Tie")),"Check score")) -> Kunal D + Anirudha H | K17: 21-18 | L17: =IF(K17="","",IFERROR(IF(--_xlfn.TEXTBEFORE(K17,"-")>--_xlfn.TEXTAFTER(K17,"-"),D17,IF(--_xlfn.TEXTAFTER(K17,"-")>--_xlfn.TEXTBEFORE(K17,"-"),E17,"Tie")),"Check score")) -> Team 3 | N17: =IFERROR(--_xlfn.TEXTBEFORE(K17,"-"),"") -> 21 | O17: =IFERROR(--_xlfn.TEXTAFTER(K17,"-"),"") -> 18 | P17: =IF(OR(N17="",O17=""),"",N17-O17) -> 3
B18: Day 2 | C18: Lunch Break | D18: Team 1 | E18: Team 4 | F18: Team 1+Team 4 | G18: Mixed Doubles | H18: Neha + Dhruv Jaju | I18: Sanjana + Bharatha S | J18: =IF(K18="","",IFERROR(IF(--_xlfn.TEXTBEFORE(K18,"-")>--_xlfn.TEXTAFTER(K18,"-"),H18,IF(--_xlfn.TEXTAFTER(K18,"-")>--_xlfn.TEXTBEFORE(K18,"-"),I18,"Tie")),"Check score")) -> Neha + Dhruv Jaju | K18: 21-17 | L18: =IF(K18="","",IFERROR(IF(--_xlfn.TEXTBEFORE(K18,"-")>--_xlfn.TEXTAFTER(K18,"-"),D18,IF(--_xlfn.TEXTAFTER(K18,"-")>--_xlfn.TEXTBEFORE(K18,"-"),E18,"Tie")),"Check score")) -> Team 1 | N18: =IFERROR(--_xlfn.TEXTBEFORE(K18,"-"),"") -> 21 | O18: =IFERROR(--_xlfn.TEXTAFTER(K18,"-"),"") -> 17 | P18: =IF(OR(N18="",O18=""),"",N18-O18) -> 4
B19: Day 2 | C19: Lunch Break | D19: Team 3 | E19: Team 4 | F19: Team 3+Team 4 | G19: Men's Singles 1 | H19: Sujal | I19: Naman | J19: =IF(K19="","",IFERROR(IF(--_xlfn.TEXTBEFORE(K19,"-")>--_xlfn.TEXTAFTER(K19,"-"),H19,IF(--_xlfn.TEXTAFTER(K19,"-")>--_xlfn.TEXTBEFORE(K19,"-"),I19,"Tie")),"Check score")) -> Sujal | K19: 21-12 | L19: =IF(K19="","",IFERROR(IF(--_xlfn.TEXTBEFORE(K19,"-")>--_xlfn.TEXTAFTER(K19,"-"),D19,IF(--_xlfn.TEXTAFTER(K19,"-")>--_xlfn.TEXTBEFORE(K19,"-"),E19,"Tie")),"Check score")) -> Team 3 | N19: =IFERROR(--_xlfn.TEXTBEFORE(K19,"-"),"") -> 21 | O19: =IFERROR(--_xlfn.TEXTAFTER(K19,"-"),"") -> 12 | P19: =IF(OR(N19="",O19=""),"",N19-O19) -> 9
B20: Day 2 | C20: Lunch Break | D20: Team 2 | E20: Team 3 | F20: Team 2+Team 3 | G20: Men's Singles 1 | H20: Dhruv C | I20: Sujal | J20: =IF(K20="","",IFERROR(IF(--_xlfn.TEXTBEFORE(K20,"-")>--_xlfn.TEXTAFTER(K20,"-"),H20,IF(--_xlfn.TEXTAFTER(K20,"-")>--_xlfn.TEXTBEFORE(K20,"-"),I20,"Tie")),"Check score")) -> Sujal | K20: 16-21 | L20: =IF(K20="","",IFERROR(IF(--_xlfn.TEXTBEFORE(K20,"-")>--_xlfn.TEXTAFTER(K20,"-"),D20,IF(--_xlfn.TEXTAFTER(K20,"-")>--_xlfn.TEXTBEFORE(K20,"-"),E20,"Tie")),"Check score")) -> Team 3 | N20: =IFERROR(--_xlfn.TEXTBEFORE(K20,"-"),"") -> 16 | O20: =IFERROR(--_xlfn.TEXTAFTER(K20,"-"),"") -> 21 | P20: =IF(OR(N20="",O20=""),"",N20-O20) -> -5
B21: Day 2 | C21: Lunch Break | D21: Team 3 | E21: Team 4 | F21: Team 3+Team 4 | G21: Mixed Doubles | H21: Rithu + Darshan Patel | I21: Sanjana + Bharatha S | J21: =IF(K21="","",IFERROR(IF(--_xlfn.TEXTBEFORE(K21,"-")>--_xlfn.TEXTAFTER(K21,"-"),H21,IF(--_xlfn.TEXTAFTER(K21,"-")>--_xlfn.TEXTBEFORE(K21,"-"),I21,"Tie")),"Check score")) -> Rithu + Darshan Patel | K21: 21-16 | L21: =IF(K21="","",IFERROR(IF(--_xlfn.TEXTBEFORE(K21,"-")>--_xlfn.TEXTAFTER(K21,"-"),D21,IF(--_xlfn.TEXTAFTER(K21,"-")>--_xlfn.TEXTBEFORE(K21,"-"),E21,"Tie")),"Check score")) -> Team 3 | N21: =IFERROR(--_xlfn.TEXTBEFORE(K21,"-"),"") -> 21 | O21: =IFERROR(--_xlfn.TEXTAFTER(K21,"-"),"") -> 16 | P21: =IF(OR(N21="",O21=""),"",N21-O21) -> 5
B22: Day 2 | C22: Lunch Break | D22: Team 1 | E22: Team 6 | F22: Team 1+Team 6 | G22: Men's Doubles 2 | H22: Sreesha + Manan | I22: Rohan + Bhuvanesh | J22: =IF(K22="","",IFERROR(IF(--_xlfn.TEXTBEFORE(K22,"-")>--_xlfn.TEXTAFTER(K22,"-"),H22,IF(--_xlfn.TEXTAFTER(K22,"-")>--_xlfn.TEXTBEFORE(K22,"-"),I22,"Tie")),"Check score")) | L22: =IF(K22="","",IFERROR(IF(--_xlfn.TEXTBEFORE(K22,"-")>--_xlfn.TEXTAFTER(K22,"-"),D22,IF(--_xlfn.TEXTAFTER(K22,"-")>--_xlfn.TEXTBEFORE(K22,"-"),E22,"Tie")),"Check score")) | M22: C | N22: =IFERROR(--_xlfn.TEXTBEFORE(K22,"-"),"") | O22: =IFERROR(--_xlfn.TEXTAFTER(K22,"-"),"") | P22: =IF(OR(N22="",O22=""),"",N22-O22)
B23: Day 2 | C23: Lunch Break | D23: Team 3 | E23: Team 5 | F23: Team 3+Team 5 | G23: Women's Singles | H23: Mamta | I23: Riya | J23: =IF(K23="","",IFERROR(IF(--_xlfn.TEXTBEFORE(K23,"-")>--_xlfn.TEXTAFTER(K23,"-"),H23,IF(--_xlfn.TEXTAFTER(K23,"-")>--_xlfn.TEXTBEFORE(K23,"-"),I23,"Tie")),"Check score")) -> Mamta | K23: 21-12 | L23: =IF(K23="","",IFERROR(IF(--_xlfn.TEXTBEFORE(K23,"-")>--_xlfn.TEXTAFTER(K23,"-"),D23,IF(--_xlfn.TEXTAFTER(K23,"-")>--_xlfn.TEXTBEFORE(K23,"-"),E23,"Tie")),"Check score")) -> Team 3 | N23: =IFERROR(--_xlfn.TEXTBEFORE(K23,"-"),"") -> 21 | O23: =IFERROR(--_xlfn.TEXTAFTER(K23,"-"),"") -> 12 | P23: =IF(OR(N23="",O23=""),"",N23-O23) -> 9
B24: Day 2 | C24: Post Office Hours | D24: Team 2 | E24: Team 6 | F24: Team 2+Team 6 | G24: Men's Singles 2 | H24: Avaneesh | I24: Navtej | J24: =IF(K24="","",IFERROR(IF(--_xlfn.TEXTBEFORE(K24,"-")>--_xlfn.TEXTAFTER(K24,"-"),H24,IF(--_xlfn.TEXTAFTER(K24,"-")>--_xlfn.TEXTBEFORE(K24,"-"),I24,"Tie")),"Check score")) -> Navtej | K24: 12-21 | L24: =IF(K24="","",IFERROR(IF(--_xlfn.TEXTBEFORE(K24,"-")>--_xlfn.TEXTAFTER(K24,"-"),D24,IF(--_xlfn.TEXTAFTER(K24,"-")>--_xlfn.TEXTBEFORE(K24,"-"),E24,"Tie")),"Check score")) -> Team 6 | N24: =IFERROR(--_xlfn.TEXTBEFORE(K24,"-"),"") -> 12 | O24: =IFERROR(--_xlfn.TEXTAFTER(K24,"-"),"") -> 21 | P24: =IF(OR(N24="",O24=""),"",N24-O24) -> -9
B25: Day 2 | C25: Post Office Hours | D25: Team 2 | E25: Team 6 | F25: Team 2+Team 6 | G25: Men's Singles 1 | H25: Dhruv C | I25: Anshul | J25: =IF(K25="","",IFERROR(IF(--_xlfn.TEXTBEFORE(K25,"-")>--_xlfn.TEXTAFTER(K25,"-"),H25,IF(--_xlfn.TEXTAFTER(K25,"-")>--_xlfn.TEXTBEFORE(K25,"-"),I25,"Tie")),"Check score")) -> Anshul | K25: 0-21 | L25: =IF(K25="","",IFERROR(IF(--_xlfn.TEXTBEFORE(K25,"-")>--_xlfn.TEXTAFTER(K25,"-"),D25,IF(--_xlfn.TEXTAFTER(K25,"-")>--_xlfn.TEXTBEFORE(K25,"-"),E25,"Tie")),"Check score")) -> Team 6 | N25: =IFERROR(--_xlfn.TEXTBEFORE(K25,"-"),"") -> 0 | O25: =IFERROR(--_xlfn.TEXTAFTER(K25,"-"),"") -> 21 | P25: =IF(OR(N25="",O25=""),"",N25-O25) -> -21
B26: Day 2 | C26: Post Office Hours | D26: Team 3 | E26: Team 6 | F26: Team 3+Team 6 | G26: Mixed Doubles | H26: Rithu + Darshan Patel | I26: Drishti + Sanath | J26: =IF(K26="","",IFERROR(IF(--_xlfn.TEXTBEFORE(K26,"-")>--_xlfn.TEXTAFTER(K26,"-"),H26,IF(--_xlfn.TEXTAFTER(K26,"-")>--_xlfn.TEXTBEFORE(K26,"-"),I26,"Tie")),"Check score")) -> Rithu + Darshan Patel | K26: 21-14 | L26: =IF(K26="","",IFERROR(IF(--_xlfn.TEXTBEFORE(K26,"-")>--_xlfn.TEXTAFTER(K26,"-"),D26,IF(--_xlfn.TEXTAFTER(K26,"-")>--_xlfn.TEXTBEFORE(K26,"-"),E26,"Tie")),"Check score")) -> Team 3 | N26: =IFERROR(--_xlfn.TEXTBEFORE(K26,"-"),"") -> 21 | O26: =IFERROR(--_xlfn.TEXTAFTER(K26,"-"),"") -> 14 | P26: =IF(OR(N26="",O26=""),"",N26-O26) -> 7
B27: Day 2 | C27: Post Office Hours | D27: Team 3 | E27: Team 6 | F27: Team 3+Team 6 | G27: Women's Singles | H27: Mamta | I27: Neha P Jain | J27: =IF(K27="","",IFERROR(IF(--_xlfn.TEXTBEFORE(K27,"-")>--_xlfn.TEXTAFTER(K27,"-"),H27,IF(--_xlfn.TEXTAFTER(K27,"-")>--_xlfn.TEXTBEFORE(K27,"-"),I27,"Tie")),"Check score")) -> Neha P Jain | K27: 11-21 | L27: =IF(K27="","",IFERROR(IF(--_xlfn.TEXTBEFORE(K27,"-")>--_xlfn.TEXTAFTER(K27,"-"),D27,IF(--_xlfn.TEXTAFTER(K27,"-")>--_xlfn.TEXTBEFORE(K27,"-"),E27,"Tie")),"Check score")) -> Team 6 | N27: =IFERROR(--_xlfn.TEXTBEFORE(K27,"-"),"") -> 11 | O27: =IFERROR(--_xlfn.TEXTAFTER(K27,"-"),"") -> 21 | P27: =IF(OR(N27="",O27=""),"",N27-O27) -> -10
B28: Day 2 | C28: Post Office Hours | D28: Team 2 | E28: Team 3 | F28: Team 2+Team 3 | G28: Men's Doubles 2 | H28: Yuvraj + Karthik KB | I28: Sarvesh H + Deviprasad | J28: =IF(K28="","",IFERROR(IF(--_xlfn.TEXTBEFORE(K28,"-")>--_xlfn.TEXTAFTER(K28,"-"),H28,IF(--_xlfn.TEXTAFTER(K28,"-")>--_xlfn.TEXTBEFORE(K28,"-"),I28,"Tie")),"Check score")) -> Sarvesh H + Deviprasad | K28: 17-21 | L28: =IF(K28="","",IFERROR(IF(--_xlfn.TEXTBEFORE(K28,"-")>--_xlfn.TEXTAFTER(K28,"-"),D28,IF(--_xlfn.TEXTAFTER(K28,"-")>--_xlfn.TEXTBEFORE(K28,"-"),E28,"Tie")),"Check score")) -> Team 3 | N28: =IFERROR(--_xlfn.TEXTBEFORE(K28,"-"),"") -> 17 | O28: =IFERROR(--_xlfn.TEXTAFTER(K28,"-"),"") -> 21 | P28: =IF(OR(N28="",O28=""),"",N28-O28) -> -4
B29: Day 2 | C29: Post Office Hours | D29: Team 1 | E29: Team 5 | F29: Team 1+Team 5 | G29: Men's Doubles 2 | H29: Sreesha + Manan | I29: Rohith + Darshan H | J29: =IF(K29="","",IFERROR(IF(--_xlfn.TEXTBEFORE(K29,"-")>--_xlfn.TEXTAFTER(K29,"-"),H29,IF(--_xlfn.TEXTAFTER(K29,"-")>--_xlfn.TEXTBEFORE(K29,"-"),I29,"Tie")),"Check score")) -> Sreesha + Manan | K29: 21-10 | L29: =IF(K29="","",IFERROR(IF(--_xlfn.TEXTBEFORE(K29,"-")>--_xlfn.TEXTAFTER(K29,"-"),D29,IF(--_xlfn.TEXTAFTER(K29,"-")>--_xlfn.TEXTBEFORE(K29,"-"),E29,"Tie")),"Check score")) -> Team 1 | N29: =IFERROR(--_xlfn.TEXTBEFORE(K29,"-"),"") -> 21 | O29: =IFERROR(--_xlfn.TEXTAFTER(K29,"-"),"") -> 10 | P29: =IF(OR(N29="",O29=""),"",N29-O29) -> 11
B30: Day 2 | C30: Post Office Hours | D30: Team 5 | E30: Team 6 | F30: Team 5+Team 6 | G30: Men's Singles 1 | H30: Pavan D | I30: Anshul | J30: =IF(K30="","",IFERROR(IF(--_xlfn.TEXTBEFORE(K30,"-")>--_xlfn.TEXTAFTER(K30,"-"),H30,IF(--_xlfn.TEXTAFTER(K30,"-")>--_xlfn.TEXTBEFORE(K30,"-"),I30,"Tie")),"Check score")) -> Pavan D | K30: 21-15 | L30: =IF(K30="","",IFERROR(IF(--_xlfn.TEXTBEFORE(K30,"-")>--_xlfn.TEXTAFTER(K30,"-"),D30,IF(--_xlfn.TEXTAFTER(K30,"-")>--_xlfn.TEXTBEFORE(K30,"-"),E30,"Tie")),"Check score")) -> Team 5 | N30: =IFERROR(--_xlfn.TEXTBEFORE(K30,"-"),"") -> 21 | O30: =IFERROR(--_xlfn.TEXTAFTER(K30,"-"),"") -> 15 | P30: =IF(OR(N30="",O30=""),"",N30-O30) -> 6
B31: Day 3 | C31: Lunch Break | D31: Team 2 | E31: Team 5 | F31: Team 2+Team 5 | G31: Men's Singles 1 | H31: Dhruv C | I31: Pavan D | J31: =IF(K31="","",IFERROR(IF(--_xlfn.TEXTBEFORE(K31,"-")>--_xlfn.TEXTAFTER(K31,"-"),H31,IF(--_xlfn.TEXTAFTER(K31,"-")>--_xlfn.TEXTBEFORE(K31,"-"),I31,"Tie")),"Check score")) -> Pavan D | K31: 7-21 | L31: =IF(K31="","",IFERROR(IF(--_xlfn.TEXTBEFORE(K31,"-")>--_xlfn.TEXTAFTER(K31,"-"),D31,IF(--_xlfn.TEXTAFTER(K31,"-")>--_xlfn.TEXTBEFORE(K31,"-"),E31,"Tie")),"Check score")) -> Team 5 | N31: =IFERROR(--_xlfn.TEXTBEFORE(K31,"-"),"") -> 7 | O31: =IFERROR(--_xlfn.TEXTAFTER(K31,"-"),"") -> 21 | P31: =IF(OR(N31="",O31=""),"",N31-O31) -> -14
B32: Day 3 | C32: Lunch Break | D32: Team 4 | E32: Team 6 | F32: Team 4+Team 6 | G32: Men's Singles 2 | H32: Jay B | I32: Navtej | J32: =IF(K32="","",IFERROR(IF(--_xlfn.TEXTBEFORE(K32,"-")>--_xlfn.TEXTAFTER(K32,"-"),H32,IF(--_xlfn.TEXTAFTER(K32,"-")>--_xlfn.TEXTBEFORE(K32,"-"),I32,"Tie")),"Check score")) -> Jay B | K32: 21-7 | L32: =IF(K32="","",IFERROR(IF(--_xlfn.TEXTBEFORE(K32,"-")>--_xlfn.TEXTAFTER(K32,"-"),D32,IF(--_xlfn.TEXTAFTER(K32,"-")>--_xlfn.TEXTBEFORE(K32,"-"),E32,"Tie")),"Check score")) -> Team 4 | N32: =IFERROR(--_xlfn.TEXTBEFORE(K32,"-"),"") -> 21 | O32: =IFERROR(--_xlfn.TEXTAFTER(K32,"-"),"") -> 7 | P32: =IF(OR(N32="",O32=""),"",N32-O32) -> 14
B33: Day 3 | C33: Lunch Break | D33: Team 2 | E33: Team 5 | F33: Team 2+Team 5 | G33: Women's Singles | H33: Vaishnavi M | I33: Riya | J33: =IF(K33="","",IFERROR(IF(--_xlfn.TEXTBEFORE(K33,"-")>--_xlfn.TEXTAFTER(K33,"-"),H33,IF(--_xlfn.TEXTAFTER(K33,"-")>--_xlfn.TEXTBEFORE(K33,"-"),I33,"Tie")),"Check score")) -> Vaishnavi M | K33: 21-14 | L33: =IF(K33="","",IFERROR(IF(--_xlfn.TEXTBEFORE(K33,"-")>--_xlfn.TEXTAFTER(K33,"-"),D33,IF(--_xlfn.TEXTAFTER(K33,"-")>--_xlfn.TEXTBEFORE(K33,"-"),E33,"Tie")),"Check score")) -> Team 2 | N33: =IFERROR(--_xlfn.TEXTBEFORE(K33,"-"),"") -> 21 | O33: =IFERROR(--_xlfn.TEXTAFTER(K33,"-"),"") -> 14 | P33: =IF(OR(N33="",O33=""),"",N33-O33) -> 7
B34: Day 3 | C34: Lunch Break | D34: Team 4 | E34: Team 6 | F34: Team 4+Team 6 | G34: Men's Doubles 2 | H34: Khush B + Hemanth | I34: Rohan + Bhuvanesh | J34: =IF(K34="","",IFERROR(IF(--_xlfn.TEXTBEFORE(K34,"-")>--_xlfn.TEXTAFTER(K34,"-"),H34,IF(--_xlfn.TEXTAFTER(K34,"-")>--_xlfn.TEXTBEFORE(K34,"-"),I34,"Tie")),"Check score")) -> Rohan + Bhuvanesh | K34: 13-21 | L34: =IF(K34="","",IFERROR(IF(--_xlfn.TEXTBEFORE(K34,"-")>--_xlfn.TEXTAFTER(K34,"-"),D34,IF(--_xlfn.TEXTAFTER(K34,"-")>--_xlfn.TEXTBEFORE(K34,"-"),E34,"Tie")),"Check score")) -> Team 6 | N34: =IFERROR(--_xlfn.TEXTBEFORE(K34,"-"),"") -> 13 | O34: =IFERROR(--_xlfn.TEXTAFTER(K34,"-"),"") -> 21 | P34: =IF(OR(N34="",O34=""),"",N34-O34) -> -8
... B49: Day 4 | C49: Lunch Break | D49: Team 1 | E49: Team 2 | F49: Team 1+Team 2 | G49: Men's Doubles 2 | H49: Sreesha + Manan | I49: Yuvraj + Karthik KB | J49: =IF(K49="","",IFERROR(IF(--_xlfn.TEXTBEFORE(K49,"-")>--_xlfn.TEXTAFTER(K49,"-"),H49,IF(--_xlfn.TEXTAFTER(K49,"-")>--_xlfn.TEXTBEFORE(K49,"-"),I49,"Tie")),"Check score")) -> Yuvraj + Karthik KB | K49: 08-21 | L49: =IF(K49="","",IFERROR(IF(--_xlfn.TEXTBEFORE(K49,"-")>--_xlfn.TEXTAFTER(K49,"-"),D49,IF(--_xlfn.TEXTAFTER(K49,"-")>--_xlfn.TEXTBEFORE(K49,"-"),E49,"Tie")),"Check score")) -> Team 2 | N49: =IFERROR(--_xlfn.TEXTBEFORE(K49,"-"),"") -> 8 | O49: =IFERROR(--_xlfn.TEXTAFTER(K49,"-"),"") -> 21 | P49: =IF(OR(N49="",O49=""),"",N49-O49) -> -13
B50: Day 4 | C50: Lunch Break | D50: Team 2 | E50: Team 6 | F50: Team 2+Team 6 | G50: Women's Doubles | H50: Vaishnavi M + Keerthana | I50: Neha P Jain + Drishti | J50: =IF(K50="","",IFERROR(IF(--_xlfn.TEXTBEFORE(K50,"-")>--_xlfn.TEXTAFTER(K50,"-"),H50,IF(--_xlfn.TEXTAFTER(K50,"-")>--_xlfn.TEXTBEFORE(K50,"-"),I50,"Tie")),"Check score")) | L50: =IF(K50="","",IFERROR(IF(--_xlfn.TEXTBEFORE(K50,"-")>--_xlfn.TEXTAFTER(K50,"-"),D50,IF(--_xlfn.TEXTAFTER(K50,"-")>--_xlfn.TEXTBEFORE(K50,"-"),E50,"Tie")),"Check score")) | M50: C | N50: =IFERROR(--_xlfn.TEXTBEFORE(K50,"-"),"") | O50: =IFERROR(--_xlfn.TEXTAFTER(K50,"-"),"") | P50: =IF(OR(N50="",O50=""),"",N50-O50)
B51: Day 4 | C51: Lunch Break | D51: Team 3 | E51: Team 4 | F51: Team 3+Team 4 | G51: Women's Doubles | H51: Mamta + Rithu | I51: Subashree + Sanjana | J51: =IF(K51="","",IFERROR(IF(--_xlfn.TEXTBEFORE(K51,"-")>--_xlfn.TEXTAFTER(K51,"-"),H51,IF(--_xlfn.TEXTAFTER(K51,"-")>--_xlfn.TEXTBEFORE(K51,"-"),I51,"Tie")),"Check score")) -> Subashree + Sanjana | K51: 16-21 | L51: =IF(K51="","",IFERROR(IF(--_xlfn.TEXTBEFORE(K51,"-")>--_xlfn.TEXTAFTER(K51,"-"),D51,IF(--_xlfn.TEXTAFTER(K51,"-")>--_xlfn.TEXTBEFORE(K51,"-"),E51,"Tie")),"Check score")) -> Team 4 | N51: =IFERROR(--_xlfn.TEXTBEFORE(K51,"-"),"") -> 16 | O51: =IFERROR(--_xlfn.TEXTAFTER(K51,"-"),"") -> 21 | P51: =IF(OR(N51="",O51=""),"",N51-O51) -> -5
B52: Day 4 | C52: Post Office Hours | D52: Team 1 | E52: Team 5 | F52: Team 1+Team 5 | G52: Mixed Doubles | H52: Neha + Dhruv Jaju | I52: Yukti + Niranjan | J52: =IF(K52="","",IFERROR(IF(--_xlfn.TEXTBEFORE(K52,"-")>--_xlfn.TEXTAFTER(K52,"-"),H52,IF(--_xlfn.TEXTAFTER(K52,"-")>--_xlfn.TEXTBEFORE(K52,"-"),I52,"Tie")),"Check score")) -> Yukti + Niranjan | K52: 15-21 | L52: =IF(K52="","",IFERROR(IF(--_xlfn.TEXTBEFORE(K52,"-")>--_xlfn.TEXTAFTER(K52,"-"),D52,IF(--_xlfn.TEXTAFTER(K52,"-")>--_xlfn.TEXTBEFORE(K52,"-"),E52,"Tie")),"Check score")) -> Team 5 | N52: =IFERROR(--_xlfn.TEXTBEFORE(K52,"-"),"") -> 15 | O52: =IFERROR(--_xlfn.TEXTAFTER(K52,"-"),"") -> 21 | P52: =IF(OR(N52="",O52=""),"",N52-O52) -> -6
B53: Day 4 | C53: Post Office Hours | D53: Team 1 | E53: Team 5 | F53: Team 1+Team 5 | G53: Women's Singles | H53: Amrutha | I53: Riya | J53: =IF(K53="","",IFERROR(IF(--_xlfn.TEXTBEFORE(K53,"-")>--_xlfn.TEXTAFTER(K53,"-"),H53,IF(--_xlfn.TEXTAFTER(K53,"-")>--_xlfn.TEXTBEFORE(K53,"-"),I53,"Tie")),"Check score")) -> Amrutha | K53: 21-16 | L53: =IF(K53="","",IFERROR(IF(--_xlfn.TEXTBEFORE(K53,"-")>--_xlfn.TEXTAFTER(K53,"-"),D53,IF(--_xlfn.TEXTAFTER(K53,"-")>--_xlfn.TEXTBEFORE(K53,"-"),E53,"Tie")),"Check score")) -> Team 1 | N53: =IFERROR(--_xlfn.TEXTBEFORE(K53,"-"),"") -> 21 | O53: =IFERROR(--_xlfn.TEXTAFTER(K53,"-"),"") -> 16 | P53: =IF(OR(N53="",O53=""),"",N53-O53) -> 5
B54: Day 4 | C54: Post Office Hours | D54: Team 4 | E54: Team 6 | F54: Team 4+Team 6 | G54: Men's Singles 1 | H54: Naman | I54: Anshul | J54: =IF(K54="","",IFERROR(IF(--_xlfn.TEXTBEFORE(K54,"-")>--_xlfn.TEXTAFTER(K54,"-"),H54,IF(--_xlfn.TEXTAFTER(K54,"-")>--_xlfn.TEXTBEFORE(K54,"-"),I54,"Tie")),"Check score")) -> Naman | K54: 21-18 | L54: =IF(K54="","",IFERROR(IF(--_xlfn.TEXTBEFORE(K54,"-")>--_xlfn.TEXTAFTER(K54,"-"),D54,IF(--_xlfn.TEXTAFTER(K54,"-")>--_xlfn.TEXTBEFORE(K54,"-"),E54,"Tie")),"Check score")) -> Team 4 | N54: =IFERROR(--_xlfn.TEXTBEFORE(K54,"-"),"") -> 21 | O54: =IFERROR(--_xlfn.TEXTAFTER(K54,"-"),"") -> 18 | P54: =IF(OR(N54="",O54=""),"",N54-O54) -> 3
B55: Day 4 | C55: Post Office Hours | D55: Team 1 | E55: Team 3 | F55: Team 1+Team 3 | G55: Men's Doubles 2 | H55: Sreesha + Manan | I55: Sarvesh H + Deviprasad | J55: =IF(K55="","",IFERROR(IF(--_xlfn.TEXTBEFORE(K55,"-")>--_xlfn.TEXTAFTER(K55,"-"),H55,IF(--_xlfn.TEXTAFTER(K55,"-")>--_xlfn.TEXTBEFORE(K55,"-"),I55,"Tie")),"Check score")) -> Sarvesh H + Deviprasad | K55: 22-24 | L55: =IF(K55="","",IFERROR(IF(--_xlfn.TEXTBEFORE(K55,"-")>--_xlfn.TEXTAFTER(K55,"-"),D55,IF(--_xlfn.TEXTAFTER(K55,"-")>--_xlfn.TEXTBEFORE(K55,"-"),E55,"Tie")),"Check score")) -> Team 3 | N55: =IFERROR(--_xlfn.TEXTBEFORE(K55,"-"),"") -> 22 | O55: =IFERROR(--_xlfn.TEXTAFTER(K55,"-"),"") -> 24 | P55: =IF(OR(N55="",O55=""),"",N55-O55) -> -2
...

Sheet Standings
A1: Tournament Standings & Qualification
A2: Each completed win earns 2 points; losses earn 0. Rank by total points, then score difference (points for minus points against), then team number.
A3: Master Score Table
A4: Team | B4: Women's Singles | C4: Women's Doubles | D4: Mixed Doubles | E4: Men's Singles 1 | F4: Men's Singles 2 | G4: Men's Doubles 1 | H4: Men's Doubles 2 | I4: Total Points | J4: Difference | K4: Rank | L4: Status
A5: Team 1 | B5: ='Points Table'!D16 -> 4 | C5: ='Points Table'!D26 -> 10 | D5: ='Points Table'!D36 -> 4 | E5: ='Points Table'!D46 -> 6 | F5: ='Points Table'!D56 -> 6 | G5: ='Points Table'!D66 -> 2 | H5: ='Points Table'!D76 -> 2 | I5: =SUM(B5:H5) -> 34 | J5: ='Points Table'!G6 -> -17 | K5: =1+COUNTIF($I$5:$I$10,">"&I5)+COUNTIFS($I$5:$I$10,I5,$J$5:$J$10,">"&J5)+COUNTIFS($I$5:$I$10,I5,$J$5:$J$10,J5,$A$5:$A$10,"<"&A5) -> 5 | L5: =IF(COUNTA('Shuffled Matches'!$K$3:$K$107)=0,"Pending",IF(K5<=4,"Qualified","Not Qualified")) -> Not Qualified
A6: Team 2 | B6: ='Points Table'!D17 -> 8 | C6: ='Points Table'!D27 -> 6 | D6: ='Points Table'!D37 -> 8 | E6: ='Points Table'!D47 -> 0 | F6: ='Points Table'!D57 -> 0 | G6: ='Points Table'!D67 -> 10 | H6: ='Points Table'!D77 -> 6 | I6: =SUM(B6:H6) -> 38 | J6: ='Points Table'!G7 -> -33 | K6: =1+COUNTIF($I$5:$I$10,">"&I6)+COUNTIFS($I$5:$I$10,I6,$J$5:$J$10,">"&J6)+COUNTIFS($I$5:$I$10,I6,$J$5:$J$10,J6,$A$5:$A$10,"<"&A6) -> 3 | L6: =IF(COUNTA('Shuffled Matches'!$K$3:$K$107)=0,"Pending",IF(K6<=4,"Qualified","Not Qualified")) -> Qualified
A7: Team 3 | B7: ='Points Table'!D18 -> 4 | C7: ='Points Table'!D28 -> 2 | D7: ='Points Table'!D38 -> 10 | E7: ='Points Table'!D48 -> 8 | F7: ='Points Table'!D58 -> 2 | G7: ='Points Table'!D68 -> 8 | H7: ='Points Table'!D78 -> 8 | I7: =SUM(B7:H7) -> 42 | J7: ='Points Table'!G8 -> 21 | K7: =1+COUNTIF($I$5:$I$10,">"&I7)+COUNTIFS($I$5:$I$10,I7,$J$5:$J$10,">"&J7)+COUNTIFS($I$5:$I$10,I7,$J$5:$J$10,J7,$A$5:$A$10,"<"&A7) -> 1 | L7: =IF(COUNTA('Shuffled Matches'!$K$3:$K$107)=0,"Pending",IF(K7<=4,"Qualified","Not Qualified")) -> Qualified
A8: Team 4 | B8: ='Points Table'!D19 -> 4 | C8: ='Points Table'!D29 -> 6 | D8: ='Points Table'!D39 -> 4 | E8: ='Points Table'!D49 -> 4 | F8: ='Points Table'!D59 -> 10 | G8: ='Points Table'!D69 -> 6 | H8: ='Points Table'!D79 -> 4 | I8: =SUM(B8:H8) -> 38 | J8: ='Points Table'!G9 -> 113 | K8: =1+COUNTIF($I$5:$I$10,">"&I8)+COUNTIFS($I$5:$I$10,I8,$J$5:$J$10,">"&J8)+COUNTIFS($I$5:$I$10,I8,$J$5:$J$10,J8,$A$5:$A$10,"<"&A8) -> 2 | L8: =IF(COUNTA('Shuffled Matches'!$K$3:$K$107)=0,"Pending",IF(K8<=4,"Qualified","Not Qualified")) -> Qualified
A9: Team 5 | B9: ='Points Table'!D20 -> 0 | C9: ='Points Table'!D30 -> 0 | D9: ='Points Table'!D40 -> 4 | E9: ='Points Table'!D50 -> 8 | F9: ='Points Table'!D60 -> 8 | G9: ='Points Table'!D70 -> 0 | H9: ='Points Table'!D80 -> 0 | I9: =SUM(B9:H9) -> 20 | J9: ='Points Table'!G10 -> -123 | K9: =1+COUNTIF($I$5:$I$10,">"&I9)+COUNTIFS($I$5:$I$10,I9,$J$5:$J$10,">"&J9)+COUNTIFS($I$5:$I$10,I9,$J$5:$J$10,J9,$A$5:$A$10,"<"&A9) -> 6 | L9: =IF(COUNTA('Shuffled Matches'!$K$3:$K$107)=0,"Pending",IF(K9<=4,"Qualified","Not Qualified")) -> Not Qualified
A10: Team 6 | B10: ='Points Table'!D21 -> 10 | C10: ='Points Table'!D31 -> 4 | D10: ='Points Table'!D41 -> 0 | E10: ='Points Table'!D51 -> 4 | F10: ='Points Table'!D61 -> 4 | G10: ='Points Table'!D71 -> 4 | H10: ='Points Table'!D81 -> 8 | I10: =SUM(B10:H10) -> 34 | J10: ='Points Table'!G11 -> 39 | K10: =1+COUNTIF($I$5:$I$10,">"&I10)+COUNTIFS($I$5:$I$10,I10,$J$5:$J$10,">"&J10)+COUNTIFS($I$5:$I$10,I10,$J$5:$J$10,J10,$A$5:$A$10,"<"&A10) -> 4 | L10: =IF(COUNTA('Shuffled Matches'!$K$3:$K$107)=0,"Pending",IF(K10<=4,"Qualified","Not Qualified")) -> Qualified
A13: Top 4 Qualifiers
A14: Rank | B14: Team | C14: Total Points | D14: Difference
A15: 1 | B15: =IF(COUNTA('Shuffled Matches'!$K$3:$K$107)=0,"",_xlfn.XLOOKUP(A15,$K$5:$K$10,$A$5:$A$10,"")) -> Team 3 | C15: =IF(B15="","",_xlfn.XLOOKUP(A15,$K$5:$K$10,$I$5:$I$10,"")) -> 42 | D15: =IF(B15="","",_xlfn.XLOOKUP(A15,$K$5:$K$10,$J$5:$J$10,"")) -> 21
A16: 2 | B16: =IF(COUNTA('Shuffled Matches'!$K$3:$K$107)=0,"",_xlfn.XLOOKUP(A16,$K$5:$K$10,$A$5:$A$10,"")) -> Team 4 | C16: =IF(B16="","",_xlfn.XLOOKUP(A16,$K$5:$K$10,$I$5:$I$10,"")) -> 38 | D16: =IF(B16="","",_xlfn.XLOOKUP(A16,$K$5:$K$10,$J$5:$J$10,"")) -> 113
A17: 3 | B17: =IF(COUNTA('Shuffled Matches'!$K$3:$K$107)=0,"",_xlfn.XLOOKUP(A17,$K$5:$K$10,$A$5:$A$10,"")) -> Team 2 | C17: =IF(B17="","",_xlfn.XLOOKUP(A17,$K$5:$K$10,$I$5:$I$10,"")) -> 38 | D17: =IF(B17="","",_xlfn.XLOOKUP(A17,$K$5:$K$10,$J$5:$J$10,"")) -> -33
A18: 4 | B18: =IF(COUNTA('Shuffled Matches'!$K$3:$K$107)=0,"",_xlfn.XLOOKUP(A18,$K$5:$K$10,$A$5:$A$10,"")) -> Team 6 | C18: =IF(B18="","",_xlfn.XLOOKUP(A18,$K$5:$K$10,$I$5:$I$10,"")) -> 34 | D18: =IF(B18="","",_xlfn.XLOOKUP(A18,$K$5:$K$10,$J$5:$J$10,"")) -> 39

Sheet Format Scoreboards
B2: Women's Singles Scoreboard
B3: Ranking: 2 points per win, 0 per loss; ties broken by score difference.
B4: Team | C4: Points | D4: Difference | E4: Rank | F4: Status | H4: Rank | I4: Top 4 Team | J4: Points | K4: Difference | L4: Raw Score
B5: Team 1 | C5: ='Points Table'!D16 -> 4 | D5: ='Points Table'!G16 -> -22 | E5: =1+COUNTIF($C$5:$C$10,">"&C5)+COUNTIFS($C$5:$C$10,C5,$D$5:$D$10,">"&D5)+COUNTIFS($C$5:$C$10,C5,$D$5:$D$10,D5,$B$5:$B$10,"<"&B5) -> 5 | F5: =IF(COUNTIFS('Shuffled Matches'!$G$3:$G$107,"Women's Singles",'Shuffled Matches'!$K$3:$K$107,"<>")=0,"Pending",IF(E5<=4,"Top 4","Eliminated")) -> Eliminated | H5: 1 | I5: =IF(COUNTIFS('Shuffled Matches'!$G$3:$G$107,"Women's Singles",'Shuffled Matches'!$K$3:$K$107,"<>")=0,"",_xlfn.XLOOKUP(H5,$E$5:$E$10,$B$5:$B$10,"")) -> Team 6 | J5: =IF(I5="","",_xlfn.XLOOKUP(H5,$E$5:$E$10,$C$5:$C$10,"")) -> 10 | K5: =IF(I5="","",_xlfn.XLOOKUP(H5,$E$5:$E$10,$D$5:$D$10,"")) -> 51 | L5: ='Points Table'!E16 -> 75
B6: Team 2 | C6: ='Points Table'!D17 -> 8 | D6: ='Points Table'!G17 -> 8 | E6: =1+COUNTIF($C$5:$C$10,">"&C6)+COUNTIFS($C$5:$C$10,C6,$D$5:$D$10,">"&D6)+COUNTIFS($C$5:$C$10,C6,$D$5:$D$10,D6,$B$5:$B$10,"<"&B6) -> 2 | F6: =IF(COUNTIFS('Shuffled Matches'!$G$3:$G$107,"Women's Singles",'Shuffled Matches'!$K$3:$K$107,"<>")=0,"Pending",IF(E6<=4,"Top 4","Eliminated")) -> Top 4 | H6: 2 | I6: =IF(COUNTIFS('Shuffled Matches'!$G$3:$G$107,"Women's Singles",'Shuffled Matches'!$K$3:$K$107,"<>")=0,"",_xlfn.XLOOKUP(H6,$E$5:$E$10,$B$5:$B$10,"")) -> Team 2 | J6: =IF(I6="","",_xlfn.XLOOKUP(H6,$E$5:$E$10,$C$5:$C$10,"")) -> 8 | K6: =IF(I6="","",_xlfn.XLOOKUP(H6,$E$5:$E$10,$D$5:$D$10,"")) -> 8 | L6: ='Points Table'!E17 -> 90
B7: Team 3 | C7: ='Points Table'!D18 -> 4 | D7: ='Points Table'!G18 -> -8 | E7: =1+COUNTIF($C$5:$C$10,">"&C7)+COUNTIFS($C$5:$C$10,C7,$D$5:$D$10,">"&D7)+COUNTIFS($C$5:$C$10,C7,$D$5:$D$10,D7,$B$5:$B$10,"<"&B7) -> 4 | F7: =IF(COUNTIFS('Shuffled Matches'!$G$3:$G$107,"Women's Singles",'Shuffled Matches'!$K$3:$K$107,"<>")=0,"Pending",IF(E7<=4,"Top 4","Eliminated")) -> Top 4 | H7: 3 | I7: =IF(COUNTIFS('Shuffled Matches'!$G$3:$G$107,"Women's Singles",'Shuffled Matches'!$K$3:$K$107,"<>")=0,"",_xlfn.XLOOKUP(H7,$E$5:$E$10,$B$5:$B$10,"")) -> Team 4 | J7: =IF(I7="","",_xlfn.XLOOKUP(H7,$E$5:$E$10,$C$5:$C$10,"")) -> 4 | K7: =IF(I7="","",_xlfn.XLOOKUP(H7,$E$5:$E$10,$D$5:$D$10,"")) -> 14 | L7: ='Points Table'!E18 -> 86
B8: Team 4 | C8: ='Points Table'!D19 -> 4 | D8: ='Points Table'!G19 -> 14 | E8: =1+COUNTIF($C$5:$C$10,">"&C8)+COUNTIFS($C$5:$C$10,C8,$D$5:$D$10,">"&D8)+COUNTIFS($C$5:$C$10,C8,$D$5:$D$10,D8,$B$5:$B$10,"<"&B8) -> 3 | F8: =IF(COUNTIFS('Shuffled Matches'!$G$3:$G$107,"Women's Singles",'Shuffled Matches'!$K$3:$K$107,"<>")=0,"Pending",IF(E8<=4,"Top 4","Eliminated")) -> Top 4 | H8: 4 | I8: =IF(COUNTIFS('Shuffled Matches'!$G$3:$G$107,"Women's Singles",'Shuffled Matches'!$K$3:$K$107,"<>")=0,"",_xlfn.XLOOKUP(H8,$E$5:$E$10,$B$5:$B$10,"")) -> Team 3 | J8: =IF(I8="","",_xlfn.XLOOKUP(H8,$E$5:$E$10,$C$5:$C$10,"")) -> 4 | K8: =IF(I8="","",_xlfn.XLOOKUP(H8,$E$5:$E$10,$D$5:$D$10,"")) -> -8 | L8: ='Points Table'!E19 -> 97
B9: Team 5 | C9: ='Points Table'!D20 -> 0 | D9: ='Points Table'!G20 -> -43 | E9: =1+COUNTIF($C$5:$C$10,">"&C9)+COUNTIFS($C$5:$C$10,C9,$D$5:$D$10,">"&D9)+COUNTIFS($C$5:$C$10,C9,$D$5:$D$10,D9,$B$5:$B$10,"<"&B9) -> 6 | F9: =IF(COUNTIFS('Shuffled Matches'!$G$3:$G$107,"Women's Singles",'Shuffled Matches'!$K$3:$K$107,"<>")=0,"Pending",IF(E9<=4,"Top 4","Eliminated")) -> Eliminated | L9: ='Points Table'!E20 -> 62
B10: Team 6 | C10: ='Points Table'!D21 -> 10 | D10: ='Points Table'!G21 -> 51 | E10: =1+COUNTIF($C$5:$C$10,">"&C10)+COUNTIFS($C$5:$C$10,C10,$D$5:$D$10,">"&D10)+COUNTIFS($C$5:$C$10,C10,$D$5:$D$10,D10,$B$5:$B$10,"<"&B10) -> 1 | F10: =IF(COUNTIFS('Shuffled Matches'!$G$3:$G$107,"Women's Singles",'Shuffled Matches'!$K$3:$K$107,"<>")=0,"Pending",IF(E10<=4,"Top 4","Eliminated")) -> Top 4 | L10: ='Points Table'!E21 -> 105
B16: Women's Doubles Scoreboard
B17: Ranking: 2 points per win, 0 per loss; ties broken by score difference.
B18: Team | C18: Points | D18: Difference | E18: Rank | F18: Status | H18: Rank | I18: Top 4 Team | J18: Points | K18: Difference | L18: Raw Score
B19: Team 1 | C19: ='Points Table'!D26 -> 10 | D19: ='Points Table'!G26 -> 29 | E19: =1+COUNTIF($C$19:$C$24,">"&C19)+COUNTIFS($C$19:$C$24,C19,$D$19:$D$24,">"&D19)+COUNTIFS($C$19:$C$24,C19,$D$19:$D$24,D19,$B$19:$B$24,"<"&B19) -> 1 | F19: =IF(COUNTIFS('Shuffled Matches'!$G$3:$G$107,"Women's Doubles",'Shuffled Matches'!$K$3:$K$107,"<>")=0,"Pending",IF(E19<=4,"Top 4","Eliminated")) -> Top 4 | H19: 1 | I19: =IF(COUNTIFS('Shuffled Matches'!$G$3:$G$107,"Women's Doubles",'Shuffled Matches'!$K$3:$K$107,"<>")=0,"",_xlfn.XLOOKUP(H19,$E$19:$E$24,$B$19:$B$24,"")) -> Team 1 | J19: =IF(I19="","",_xlfn.XLOOKUP(H19,$E$19:$E$24,$C$19:$C$24,"")) -> 10 | K19: =IF(I19="","",_xlfn.XLOOKUP(H19,$E$19:$E$24,$D$19:$D$24,"")) -> 29 | L19: ='Points Table'!E26 -> 105
B20: Team 2 | C20: ='Points Table'!D27 -> 6 | D20: ='Points Table'!G27 -> 16 | E20: =1+COUNTIF($C$19:$C$24,">"&C20)+COUNTIFS($C$19:$C$24,C20,$D$19:$D$24,">"&D20)+COUNTIFS($C$19:$C$24,C20,$D$19:$D$24,D20,$B$19:$B$24,"<"&B20) -> 3 | F20: =IF(COUNTIFS('Shuffled Matches'!$G$3:$G$107,"Women's Doubles",'Shuffled Matches'!$K$3:$K$107,"<>")=0,"Pending",IF(E20<=4,"Top 4","Eliminated")) -> Top 4 | H20: 2 | I20: =IF(COUNTIFS('Shuffled Matches'!$G$3:$G$107,"Women's Doubles",'Shuffled Matches'!$K$3:$K$107,"<>")=0,"",_xlfn.XLOOKUP(H20,$E$19:$E$24,$B$19:$B$24,"")) -> Team 4 | J20: =IF(I20="","",_xlfn.XLOOKUP(H20,$E$19:$E$24,$C$19:$C$24,"")) -> 6 | K20: =IF(I20="","",_xlfn.XLOOKUP(H20,$E$19:$E$24,$D$19:$D$24,"")) -> 18 | L20: ='Points Table'!E27 -> 81
B21: Team 3 | C21: ='Points Table'!D28 -> 2 | D21: ='Points Table'!G28 -> -24 | E21: =1+COUNTIF($C$19:$C$24,">"&C21)+COUNTIFS($C$19:$C$24,C21,$D$19:$D$24,">"&D21)+COUNTIFS($C$19:$C$24,C21,$D$19:$D$24,D21,$B$19:$B$24,"<"&B21) -> 5 | F21: =IF(COUNTIFS('Shuffled Matches'!$G$3:$G$107,"Women's Doubles",'Shuffled Matches'!$K$3:$K$107,"<>")=0,"Pending",IF(E21<=4,"Top 4","Eliminated")) -> Eliminated | H21: 3 | I21: =IF(COUNTIFS('Shuffled Matches'!$G$3:$G$107,"Women's Doubles",'Shuffled Matches'!$K$3:$K$107,"<>")=0,"",_xlfn.XLOOKUP(H21,$E$19:$E$24,$B$19:$B$24,"")) -> Team 2 | J21: =IF(I21="","",_xlfn.XLOOKUP(H21,$E$19:$E$24,$C$19:$C$24,"")) -> 6 | K21: =IF(I21="","",_xlfn.XLOOKUP(H21,$E$19:$E$24,$D$19:$D$24,"")) -> 16 | L21: ='Points Table'!E28 -> 75
B22: Team 4 | C22: ='Points Table'!D29 -> 6 | D22: ='Points Table'!G29 -> 18 | E22: =1+COUNTIF($C$19:$C$24,">"&C22)+COUNTIFS($C$19:$C$24,C22,$D$19:$D$24,">"&D22)+COUNTIFS($C$19:$C$24,C22,$D$19:$D$24,D22,$B$19:$B$24,"<"&B22) -> 2 | F22: =IF(COUNTIFS('Shuffled Matches'!$G$3:$G$107,"Women's Doubles",'Shuffled Matches'!$K$3:$K$107,"<>")=0,"Pending",IF(E22<=4,"Top 4","Eliminated")) -> Top 4 | H22: 4 | I22: =IF(COUNTIFS('Shuffled Matches'!$G$3:$G$107,"Women's Doubles",'Shuffled Matches'!$K$3:$K$107,"<>")=0,"",_xlfn.XLOOKUP(H22,$E$19:$E$24,$B$19:$B$24,"")) -> Team 6 | J22: =IF(I22="","",_xlfn.XLOOKUP(H22,$E$19:$E$24,$C$19:$C$24,"")) -> 4 | K22: =IF(I22="","",_xlfn.XLOOKUP(H22,$E$19:$E$24,$D$19:$D$24,"")) -> 4 | L22: ='Points Table'!E29 -> 96
B23: Team 5 | C23: ='Points Table'!D30 -> 0 | D23: ='Points Table'!G30 -> -43 | E23: =1+COUNTIF($C$19:$C$24,">"&C23)+COUNTIFS($C$19:$C$24,C23,$D$19:$D$24,">"&D23)+COUNTIFS($C$19:$C$24,C23,$D$19:$D$24,D23,$B$19:$B$24,"<"&B23) -> 6 | F23: =IF(COUNTIFS('Shuffled Matches'!$G$3:$G$107,"Women's Doubles",'Shuffled Matches'!$K$3:$K$107,"<>")=0,"Pending",IF(E23<=4,"Top 4","Eliminated")) -> Eliminated | L23: ='Points Table'!E30 -> 62
B24: Team 6 | C24: ='Points Table'!D31 -> 4 | D24: ='Points Table'!G31 -> 4 | E24: =1+COUNTIF($C$19:$C$24,">"&C24)+COUNTIFS($C$19:$C$24,C24,$D$19:$D$24,">"&D24)+COUNTIFS($C$19:$C$24,C24,$D$19:$D$24,D24,$B$19:$B$24,"<"&B24) -> 4 | F24: =IF(COUNTIFS('Shuffled Matches'!$G$3:$G$107,"Women's Doubles",'Shuffled Matches'!$K$3:$K$107,"<>")=0,"Pending",IF(E24<=4,"Top 4","Eliminated")) -> Top 4 | L24: ='Points Table'!E31 -> 71
B30: Mixed Doubles Scoreboard
B31: Ranking: 2 points per win, 0 per loss; ties broken by score difference.
B32: Team | C32: Points | D32: Difference | E32: Rank | F32: Status | H32: Rank | I32: Top 4 Team | J32: Points | K32: Difference | L32: Raw Score
B33: Team 1 | C33: ='Points Table'!D36 -> 4 | D33: ='Points Table'!G36 -> -1 | E33: =1+COUNTIF($C$33:$C$38,">"&C33)+COUNTIFS($C$33:$C$38,C33,$D$33:$D$38,">"&D33)+COUNTIFS($C$33:$C$38,C33,$D$33:$D$38,D33,$B$33:$B$38,"<"&B33) -> 3 | F33: =IF(COUNTIFS('Shuffled Matches'!$G$3:$G$107,"Mixed Doubles",'Shuffled Matches'!$K$3:$K$107,"<>")=0,"Pending",IF(E33<=4,"Top 4","Eliminated")) -> Top 4 | H33: 1 | I33: =IF(COUNTIFS('Shuffled Matches'!$G$3:$G$107,"Mixed Doubles",'Shuffled Matches'!$K$3:$K$107,"<>")=0,"",_xlfn.XLOOKUP(H33,$E$33:$E$38,$B$33:$B$38,"")) -> Team 3 | J33: =IF(I33="","",_xlfn.XLOOKUP(H33,$E$33:$E$38,$C$33:$C$38,"")) -> 10 | K33: =IF(I33="","",_xlfn.XLOOKUP(H33,$E$33:$E$38,$D$33:$D$38,"")) -> 30 | L33: ='Points Table'!E36 -> 86
B34: Team 2 | C34: ='Points Table'!D37 -> 8 | D34: ='Points Table'!G37 -> 29 | E34: =1+COUNTIF($C$33:$C$38,">"&C34)+COUNTIFS($C$33:$C$38,C34,$D$33:$D$38,">"&D34)+COUNTIFS($C$33:$C$38,C34,$D$33:$D$38,D34,$B$33:$B$38,"<"&B34) -> 2 | F34: =IF(COUNTIFS('Shuffled Matches'!$G$3:$G$107,"Mixed Doubles",'Shuffled Matches'!$K$3:$K$107,"<>")=0,"Pending",IF(E34<=4,"Top 4","Eliminated")) -> Top 4 | H34: 2 | I34: =IF(COUNTIFS('Shuffled Matches'!$G$3:$G$107,"Mixed Doubles",'Shuffled Matches'!$K$3:$K$107,"<>")=0,"",_xlfn.XLOOKUP(H34,$E$33:$E$38,$B$33:$B$38,"")) -> Team 2 | J34: =IF(I34="","",_xlfn.XLOOKUP(H34,$E$33:$E$38,$C$33:$C$38,"")) -> 8 | K34: =IF(I34="","",_xlfn.XLOOKUP(H34,$E$33:$E$38,$D$33:$D$38,"")) -> 29 | L34: ='Points Table'!E37 -> 100
B35: Team 3 | C35: ='Points Table'!D38 -> 10 | D35: ='Points Table'!G38 -> 30 | E35: =1+COUNTIF($C$33:$C$38,">"&C35)+COUNTIFS($C$33:$C$38,C35,$D$33:$D$38,">"&D35)+COUNTIFS($C$33:$C$38,C35,$D$33:$D$38,D35,$B$33:$B$38,"<"&B35) -> 1 | F35: =IF(COUNTIFS('Shuffled Matches'!$G$3:$G$107,"Mixed Doubles",'Shuffled Matches'!$K$3:$K$107,"<>")=0,"Pending",IF(E35<=4,"Top 4","Eliminated")) -> Top 4 | H35: 3 | I35: =IF(COUNTIFS('Shuffled Matches'!$G$3:$G$107,"Mixed Doubles",'Shuffled Matches'!$K$3:$K$107,"<>")=0,"",_xlfn.XLOOKUP(H35,$E$33:$E$38,$B$33:$B$38,"")) -> Team 1 | J35: =IF(I35="","",_xlfn.XLOOKUP(H35,$E$33:$E$38,$C$33:$C$38,"")) -> 4 | K35: =IF(I35="","",_xlfn.XLOOKUP(H35,$E$33:$E$38,$D$33:$D$38,"")) -> -1 | L35: ='Points Table'!E38 -> 105
